2023-04-10 21:28:51.499260
best_model.pth
Image Size: 32 100
Batch Size: 16
LR: 0.001
Steps: 1000000
Model A.D. Param#: 7854467
Optimizer: AdamW
Loss: CTC Loss
Setting up data...
100000
text-reg-data/base-data/special_character10
6000
text-reg-data/base-data/anotherexp
77
5000
text-reg-data/base-data/special_character10
500
text-reg-data/base-data/anotherexp
20
Dataset Size:
Train: 106077 - Valid: 5520
 - Predict: 797
Visualize augmentations...
text-reg-data/base-data/special_character10\a170DefocusBlur_1.png
Starting training...
----------
resume : saved_model\CRNN-mjsynth\best_model.pth
TRAIN [   2/1000000].     Loss: 1297.5119 - LR: 0.0001:   0%|                                                                                      | 0/6630 [00:01<?, ?it/s]
text-reg-data/base-data/special_character10\a58Snow_0.png
text-reg-data/base-data/special_character10\a118Perspective_1.png
TRAIN [   4/1000000].     Loss: 1286.6188 - LR: 0.0001:   0%|                                                                                      | 0/6630 [00:02<?, ?it/s]Traceback (most recent call last):
  File "d:\tùm lum\python\use\crnn\crnn5\data\icdardataset.py", line 139, in __getitem__
    image = Image.open(path).convert('L')  # grey-scale
  File "C:\Users\DELL\anaconda3\envs\python37\lib\site-packages\PIL\Image.py", line 3131, in open
    fp = builtins.open(filename, "rb")
FileNotFoundError: [Errno 2] No such file or directory: 'text-reg-data/base-data/anotherexp\\anotherexp/f33.png'
During handling of the above exception, another exception occurred:
Traceback (most recent call last):
  File "d:\tùm lum\python\use\crnn\crnn5\data\icdardataset.py", line 139, in __getitem__
    image = Image.open(path).convert('L')  # grey-scale
  File "C:\Users\DELL\anaconda3\envs\python37\lib\site-packages\PIL\Image.py", line 3131, in open
    fp = builtins.open(filename, "rb")
FileNotFoundError: [Errno 2] No such file or directory: 'text-reg-data/base-data/anotherexp\\anotherexp/f34.png'
During handling of the above exception, another exception occurred:
Traceback (most recent call last):
  File "d:\tùm lum\python\use\crnn\crnn5\data\icdardataset.py", line 139, in __getitem__
    image = Image.open(path).convert('L')  # grey-scale
  File "C:\Users\DELL\anaconda3\envs\python37\lib\site-packages\PIL\Image.py", line 3131, in open
    fp = builtins.open(filename, "rb")
FileNotFoundError: [Errno 2] No such file or directory: 'text-reg-data/base-data/anotherexp\\anotherexp/f35.png'
During handling of the above exception, another exception occurred:
Traceback (most recent call last):
  File "d:/tùm lum/python/use/crnn/crnn5/main.py", line 22, in <module>
    main()
  File "d:/tùm lum/python/use/crnn/crnn5/main.py", line 19, in main
    trainmodule.train_network(cfg)
  File "d:\tùm lum\python\use\crnn\crnn5\tool\base.py", line 252, in train_network
    use_wandb=cfg['TRAIN']['use_wandb']
  File "d:\tùm lum\python\use\crnn\crnn5\tool\base.py", line 287, in training
    for train_data in train_loader: # 1 batchsize train_data = 1 step
  File "C:\Users\DELL\anaconda3\envs\python37\lib\site-packages\torch\utils\data\dataloader.py", line 628, in __next__
    data = self._next_data()
  File "C:\Users\DELL\anaconda3\envs\python37\lib\site-packages\torch\utils\data\dataloader.py", line 671, in _next_data
    data = self._dataset_fetcher.fetch(index)  # may raise StopIteration
  File "C:\Users\DELL\anaconda3\envs\python37\lib\site-packages\torch\utils\data\_utils\fetch.py", line 58, in fetch
    data = [self.dataset[idx] for idx in possibly_batched_index]
  File "C:\Users\DELL\anaconda3\envs\python37\lib\site-packages\torch\utils\data\_utils\fetch.py", line 58, in <listcomp>
    data = [self.dataset[idx] for idx in possibly_batched_index]
  File "C:\Users\DELL\anaconda3\envs\python37\lib\site-packages\torch\utils\data\dataset.py", line 240, in __getitem__
    return self.datasets[dataset_idx][sample_idx]
  File "d:\tùm lum\python\use\crnn\crnn5\data\icdardataset.py", line 144, in __getitem__
    return self[index + 1]
  File "d:\tùm lum\python\use\crnn\crnn5\data\icdardataset.py", line 144, in __getitem__
    return self[index + 1]
  File "d:\tùm lum\python\use\crnn\crnn5\data\icdardataset.py", line 144, in __getitem__
    return self[index + 1]
  File "d:\tùm lum\python\use\crnn\crnn5\data\icdardataset.py", line 136, in __getitem__
    path = self.paths[index]
IndexError: list index out of range
text-reg-data/base-data/anotherexp\anotherexp/f33.png
text-reg-data/base-data/anotherexp\anotherexp/f33.png
Corrupted image for 74
text-reg-data/base-data/anotherexp\anotherexp/f34.png
text-reg-data/base-data/anotherexp\anotherexp/f34.png
Corrupted image for 75
text-reg-data/base-data/anotherexp\anotherexp/f35.png
text-reg-data/base-data/anotherexp\anotherexp/f35.png
Corrupted image for 76