2023-04-09 20:56:09,831 INFO    StreamThr :9364 [internal.py:wandb_internal():89] W&B internal server running at pid: 9364, started at: 2023-04-09 20:56:09.830413
2023-04-09 20:56:09,832 DEBUG   HandlerThread:9364 [handler.py:handle_request():144] handle_request: status
2023-04-09 20:56:09,836 INFO    WriterThread:9364 [datastore.py:open_for_write():85] open: D:\tùm lum\python\use\crnn\crnn4\wandb\run-20230409_205609-453lhpcm\run-453lhpcm.wandb
2023-04-09 20:56:09,837 DEBUG   SenderThread:9364 [sender.py:send():375] send: header
2023-04-09 20:56:09,838 DEBUG   SenderThread:9364 [sender.py:send():375] send: run
2023-04-09 20:56:10,725 ERROR   SenderThread:9364 [internal_api.py:execute():288] 403 response executing GraphQL.
2023-04-09 20:56:10,726 ERROR   SenderThread:9364 [internal_api.py:execute():289] {"errors":[{"message":"permission denied","path":["upsertBucket"],"extensions":{"code":"PERMISSION_ERROR"}}],"data":{"upsertBucket":null}}
2023-04-09 20:56:10,732 ERROR   SenderThread:9364 [sender.py:send_run():979] It appears that you do not have permission to access the requested resource. Please reach out to the project owner to grant you access. If you have the correct permissions, verify that there are no issues with your networking setup.(Error 403: Forbidden)
Traceback (most recent call last):
  File "C:\Users\DELL\anaconda3\envs\pii37\lib\site-packages\wandb\sdk\lib\retry.py", line 131, in __call__
    result = self._call_fn(*args, **kwargs)
  File "C:\Users\DELL\anaconda3\envs\pii37\lib\site-packages\wandb\sdk\internal\internal_api.py", line 285, in execute
    return self.client.execute(*args, **kwargs)  # type: ignore
  File "C:\Users\DELL\anaconda3\envs\pii37\lib\site-packages\wandb\vendor\gql-0.2.0\wandb_gql\client.py", line 52, in execute
    result = self._get_result(document, *args, **kwargs)
  File "C:\Users\DELL\anaconda3\envs\pii37\lib\site-packages\wandb\vendor\gql-0.2.0\wandb_gql\client.py", line 60, in _get_result
    return self.transport.execute(document, *args, **kwargs)
  File "C:\Users\DELL\anaconda3\envs\pii37\lib\site-packages\wandb\sdk\lib\gql_request.py", line 56, in execute
    request.raise_for_status()
  File "C:\Users\DELL\anaconda3\envs\pii37\lib\site-packages\requests\models.py", line 1021, in raise_for_status
    raise HTTPError(http_error_msg, response=self)
requests.exceptions.HTTPError: 403 Client Error: Forbidden for url: https://api.wandb.ai/graphql

During handling of the above exception, another exception occurred:

Traceback (most recent call last):
  File "C:\Users\DELL\anaconda3\envs\pii37\lib\site-packages\wandb\sdk\internal\sender.py", line 977, in send_run
    self._init_run(run, config_value_dict)
  File "C:\Users\DELL\anaconda3\envs\pii37\lib\site-packages\wandb\sdk\internal\sender.py", line 1029, in _init_run
    commit=run.git.commit or None,
  File "C:\Users\DELL\anaconda3\envs\pii37\lib\site-packages\wandb\apis\normalize.py", line 73, in wrapper
    raise err
  File "C:\Users\DELL\anaconda3\envs\pii37\lib\site-packages\wandb\apis\normalize.py", line 41, in wrapper
    return func(*args, **kwargs)
  File "C:\Users\DELL\anaconda3\envs\pii37\lib\site-packages\wandb\sdk\internal\internal_api.py", line 1694, in upsert_run
    **kwargs,
  File "C:\Users\DELL\anaconda3\envs\pii37\lib\site-packages\wandb\sdk\internal\internal_api.py", line 260, in gql
    **kwargs,
  File "C:\Users\DELL\anaconda3\envs\pii37\lib\site-packages\wandb\sdk\lib\retry.py", line 147, in __call__
    retry_timedelta_triggered = check_retry_fn(e)
  File "C:\Users\DELL\anaconda3\envs\pii37\lib\site-packages\wandb\util.py", line 950, in check_retry_fn
    return fallback_retry_fn(e)
  File "C:\Users\DELL\anaconda3\envs\pii37\lib\site-packages\wandb\util.py", line 893, in no_retry_auth
    "It appears that you do not have permission to access the requested resource. "
wandb.errors.CommError: It appears that you do not have permission to access the requested resource. Please reach out to the project owner to grant you access. If you have the correct permissions, verify that there are no issues with your networking setup.(Error 403: Forbidden)
2023-04-09 20:56:11,189 DEBUG   HandlerThread:9364 [handler.py:handle_request():144] handle_request: shutdown
2023-04-09 20:56:11,189 INFO    HandlerThread:9364 [handler.py:finish():845] shutting down handler
2023-04-09 20:56:11,754 INFO    SenderThread:9364 [sender.py:finish():1550] shutting down sender
2023-04-09 20:56:11,862 INFO    WriterThread:9364 [datastore.py:close():298] close: D:\tùm lum\python\use\crnn\crnn4\wandb\run-20230409_205609-453lhpcm\run-453lhpcm.wandb
