2023-04-10 20:30:48.340463
best_model.pth
Image Size: 32 100
Batch Size: 16
LR: 0.003
Steps: 1000000
Model A.D. Param#: 7854467
Optimizer: AdamW
Loss: CTC Loss
Setting up data...
100000
text-reg-data/base-data/special_character11
200
text-reg-data/base-data/anotherexp
77
5000
text-reg-data/base-data/special_character11
40
text-reg-data/base-data/anotherexp
20
Dataset Size:
Train: 100277 - Valid: 5060
 - Predict: 897
Visualize augmentations...
Starting training...
----------
resume : saved_model\CRNN-mjsynth\best_model.pth


TRAIN [  11/1000000].     Loss: 1207.7112 - LR: 0.0001:   0%|                                                                                      | 0/6268 [00:06<?, ?it/s]
text-reg-data/base-data/special_character11\special_character11/a197.png
text-reg-data/base-data/special_character11\special_character11/a197.png
Corrupted image for 197
text-reg-data/base-data/special_character11\special_character11/a198.png
text-reg-data/base-data/special_character11\special_character11/a198.png
Corrupted image for 198
text-reg-data/base-data/special_character11\special_character11/a199.png
text-reg-data/base-data/special_character11\special_character11/a199.png
TRAIN [  14/1000000].     Loss: 1152.1895 - LR: 0.0001:   0%|                                                                                      | 0/6268 [00:07<?, ?it/s]Traceback (most recent call last):
  File "d:\tùm lum\python\use\crnn\crnn5\data\icdardataset.py", line 168, in __getitem__
    image = Image.open(path).convert('L')  # grey-scale
  File "C:\Users\DELL\anaconda3\envs\python37\lib\site-packages\PIL\Image.py", line 3131, in open
    fp = builtins.open(filename, "rb")
FileNotFoundError: [Errno 2] No such file or directory: 'text-reg-data/base-data/special_character11\\special_character11/a197.png'
During handling of the above exception, another exception occurred:
Traceback (most recent call last):
  File "d:\tùm lum\python\use\crnn\crnn5\data\icdardataset.py", line 168, in __getitem__
    image = Image.open(path).convert('L')  # grey-scale
  File "C:\Users\DELL\anaconda3\envs\python37\lib\site-packages\PIL\Image.py", line 3131, in open
    fp = builtins.open(filename, "rb")
FileNotFoundError: [Errno 2] No such file or directory: 'text-reg-data/base-data/special_character11\\special_character11/a198.png'
During handling of the above exception, another exception occurred:
Traceback (most recent call last):
  File "d:\tùm lum\python\use\crnn\crnn5\data\icdardataset.py", line 168, in __getitem__
    image = Image.open(path).convert('L')  # grey-scale
  File "C:\Users\DELL\anaconda3\envs\python37\lib\site-packages\PIL\Image.py", line 3131, in open
    fp = builtins.open(filename, "rb")
FileNotFoundError: [Errno 2] No such file or directory: 'text-reg-data/base-data/special_character11\\special_character11/a199.png'
During handling of the above exception, another exception occurred:
Traceback (most recent call last):
  File "d:/tùm lum/python/use/crnn/crnn5/main.py", line 22, in <module>
    main()
  File "d:/tùm lum/python/use/crnn/crnn5/main.py", line 19, in main
    trainmodule.train_network(cfg)
  File "d:\tùm lum\python\use\crnn\crnn5\tool\base.py", line 256, in train_network
    use_wandb=cfg['TRAIN']['use_wandb']
  File "d:\tùm lum\python\use\crnn\crnn5\tool\base.py", line 291, in training
    for train_data in train_loader: # 1 batchsize train_data = 1 step
  File "C:\Users\DELL\anaconda3\envs\python37\lib\site-packages\torch\utils\data\dataloader.py", line 628, in __next__
    data = self._next_data()
  File "C:\Users\DELL\anaconda3\envs\python37\lib\site-packages\torch\utils\data\dataloader.py", line 671, in _next_data
    data = self._dataset_fetcher.fetch(index)  # may raise StopIteration
  File "C:\Users\DELL\anaconda3\envs\python37\lib\site-packages\torch\utils\data\_utils\fetch.py", line 58, in fetch
    data = [self.dataset[idx] for idx in possibly_batched_index]
  File "C:\Users\DELL\anaconda3\envs\python37\lib\site-packages\torch\utils\data\_utils\fetch.py", line 58, in <listcomp>
    data = [self.dataset[idx] for idx in possibly_batched_index]
  File "C:\Users\DELL\anaconda3\envs\python37\lib\site-packages\torch\utils\data\dataset.py", line 240, in __getitem__
    return self.datasets[dataset_idx][sample_idx]
  File "d:\tùm lum\python\use\crnn\crnn5\data\icdardataset.py", line 173, in __getitem__
    return self[index + 1]
  File "d:\tùm lum\python\use\crnn\crnn5\data\icdardataset.py", line 173, in __getitem__
    return self[index + 1]
  File "d:\tùm lum\python\use\crnn\crnn5\data\icdardataset.py", line 173, in __getitem__
    return self[index + 1]
  File "d:\tùm lum\python\use\crnn\crnn5\data\icdardataset.py", line 165, in __getitem__
    path = self.paths[index]
IndexError: list index out of range