2023-04-09 21:18:28.972330
best_model.pth
Image Size: 32 100
Batch Size: 16
LR: 0.003
Steps: 1000000
Model A.D. Param#: 7854467
loadddd
Optimizer: AdamW
Loss: CTC Loss
Setting up data...
Dataset Size:
Train: 105000 - Valid: 5471
 - Predict: 1500
Visualize augmentations...
Starting training...
----------
resume : saved_model\CRNN-mjsynth\best_model.pth
LOAD MODEL
loaded weights from saved_model\CRNN-mjsynth\best_model.pth, step 40999, best_score 0.6748309267044416
  0%|                                                                                                                                       | 0/6563 [00:00<?, ?it/s]Traceback (most recent call last):
  File "d:/t첫m lum/python/use/crnn/crnn4/main.py", line 22, in <module>
    main()
  File "d:/t첫m lum/python/use/crnn/crnn4/main.py", line 19, in main
    trainmodule.train_network(cfg)
  File "d:\t첫m lum\python\use\crnn\crnn4\tool\trainsynth90k_special.py", line 239, in train_network
    use_wandb=cfg['TRAIN']['use_wandb']
  File "d:\t첫m lum\python\use\crnn\crnn4\tool\trainsynth90k_special.py", line 284, in training
    self.metric_monitor.getdic)
  File "C:\Users\DELL\anaconda3\envs\pii37\lib\site-packages\wandb\sdk\wandb_run.py", line 393, in wrapper
    return func(self, *args, **kwargs)
  File "C:\Users\DELL\anaconda3\envs\pii37\lib\site-packages\wandb\sdk\wandb_run.py", line 344, in wrapper_fn
    return func(self, *args, **kwargs)
  File "C:\Users\DELL\anaconda3\envs\pii37\lib\site-packages\wandb\sdk\wandb_run.py", line 334, in wrapper
    return func(self, *args, **kwargs)
  File "C:\Users\DELL\anaconda3\envs\pii37\lib\site-packages\wandb\sdk\wandb_run.py", line 1750, in log
    self._log(data=data, step=step, commit=commit)
  File "C:\Users\DELL\anaconda3\envs\pii37\lib\site-packages\wandb\sdk\wandb_run.py", line 1526, in _log
    raise ValueError("wandb.log must be passed a dictionary")
ValueError: wandb.log must be passed a dictionary